Workbook
Name P: 'Mon, Aug 31'!$A$1:$M$246
Name P.: 'Tue, Sep 01'!$A$1:$M$274

Sheet Mon, Aug 31
A1: BuildCare SCHEDULE MONDAY, AUGUST 31 / 2026
A3: SUPERVISOR ON CALL NJ: Sebastian Lopez (551) 202-4443 jlopez@build-care.com
A4: CREWS ASSIGNED BY DEFAULT ON CALL: DVM - Atlas Techs / Atlas Cleaning - HG Services
A5: CREWS CONFIRMED BY THE ON CALL: ????
A6: BC MEMBERS OFF/VACATIONS:
A7: CREW MEMBERS OFF/VACATIONS: Alluda Companies Agustin Lopez / DVM Angel Davila
D10: STATE OF NEW JERSEY
D12: WATERFRONT AREA (Fort Lee - Edgewater - Cliffside Park - Fairview - North Bergen - West New York - Weehawken - North Hoboken "8th Street Up" )
D13: BC SUPERVISOR: Carlos Perez (862) 383-3884 cperez@build-care.com BC SUPERVISOR/RUNNER: Juan Zapata (551) 202-4443 jzapata@build-care.com
A15: State | B15: MANAGEMENT | C15: BC CLERK | D15: BUILDING / ADDRESS | E15: UNIT / AREA | F15: SIZE | G15: WORKSITE STATUS | H15: JOB DESCRIPTION | I15: JOB AWARDED TO: / TECHS QUANTITY: | J15: REQUEST / P.O / WTN / W.O | K15: BC WORK ORDER / BC ESTIMATE | L15: EXTRAS | M15: SPECIAL NOTES / SEQUENCE | N15: VENDORS DAILY STATUS REPORT
A16: =IFERROR(VLOOKUP(D16,'Master sheet (Clientes)'!A$6:D$747,2,0)," ") -> NJ | B16: =IFERROR(VLOOKUP(D16,'Master sheet (Clientes)'!A$6:D$747,3,0)," ") -> Vivmark Residential | C16: =IFERROR(VLOOKUP(D16,'Master sheet (Clientes)'!A$6:D$747,4,0)," ") -> N-O | D16: Avalon at Edgewater II New Building (Russell). | E16: 104 | F16: 1BDR | G16: Occupeid | H16: Continue Repair openings that were made by other after suffering leak damage -Repairs will be in the coat closet, laundry closet, living room, hallway, bedroom, and bathroom walls. In the bathroom we will have to redo the bathroom tiles area is approximately 8x10 tiles will have to be removed, and sub floor repaired before installing new tiles at 9:00am The building will provide paint Bc to provide all other materials and labor needed to complete the job. For access, please call Christian 201-705-0879 or Alex 201-713-8719 | I16: AJ Canas Solutions Vinicio | J16: Email | N16: Continue
A17: =IFERROR(VLOOKUP(D17,'Master sheet (Clientes)'!A$6:D$747,2,0)," ") -> NJ | B17: =IFERROR(VLOOKUP(D17,'Master sheet (Clientes)'!A$6:D$747,3,0)," ") -> Vivmark Residential | C17: =IFERROR(VLOOKUP(D17,'Master sheet (Clientes)'!A$6:D$747,4,0)," ") -> N-O | D17: Avalon at Edgewater I Old Building (River Mews). | E17: 426 | G17: Occupied | H17: Make opening in guest bedroom 3x3 to reinstall loose Hvac vent, close opening, spackle, sand and paint NOTE: Bc to provide carpet film, plastic drop, spackle, mesh tape, trash bags, sanding sponge, blue tape and all other materials and labor needed to complete the job. / For access, please call Christian 201-705-0879 or Alex 201-713-8719 update the scope of work. Two more openings of 2x4 were required to see where ducts weren't connected. After the ducts were taped with duct tape, there still wasn't air flow. The building asked to please just temporarily close openings so they can do their own investigation tomorrow to see where the problem is. Once they determine and fix it, they will let us know so we can close all openings properly. | I17: AJ Canas Solutions javier | J17: Email | N17: Job placed on hold waiting new date to continue
A18: =IFERROR(VLOOKUP(D18,'Master sheet (Clientes)'!A$6:D$747,2,0)," ") -> NJ | B18: =IFERROR(VLOOKUP(D18,'Master sheet (Clientes)'!A$6:D$747,3,0)," ") -> Vivmark Residential | C18: =IFERROR(VLOOKUP(D18,'Master sheet (Clientes)'!A$6:D$747,4,0)," ") -> N-O | D18: Avalon at Edgewater II New Building (Russell). | E18: 155 | G18: Occupied | H18: Left side bedroom bathroom tile floor to be demoed, sub floor fixed, install new tiles, and grout area is 9ft x 6ft. at 9am Bc to provide all materials and labor needed to complete the job. For access, please call Christian 201-705-0879 or Alex 201-713-8719 | I18: AJ Canas Solutions Ricardo / Willian Alvarez | J18: Email | N18: Continue
A19: =IFERROR(VLOOKUP(D19,'Master sheet (Clientes)'!A$6:D$747,2,0)," ") -> NJ | B19: =IFERROR(VLOOKUP(D19,'Master sheet (Clientes)'!A$6:D$747,3,0)," ") -> Vivmark Residential | C19: =IFERROR(VLOOKUP(D19,'Master sheet (Clientes)'!A$6:D$747,4,0)," ") -> A-V | D19: The Rivington Apartments 1130 Grand St, Hoboken, NJ 07030. | E19: SG 310 | F19: 2BDR | G19: Vacant | H19: Paint unit at 8:00 am | I19: AJ Canas Solutions William Diaz | J19: Email | M19: Clean 09/02 | N19: Paint done
A21: State | B21: MANAGEMENT | C21: BC CLERK | D21: BUILDING / ADDRESS | E21: UNIT / AREA | F21: SIZE | G21: WORKSITE STATUS | H21: JOB DESCRIPTION | I21: JOB AWARDED TO: / TECHS QUANTITY: | J21: REQUEST / P.O / WTN / W.O | K21: BC WORK ORDER / BC ESTIMATE | L21: EXTRAS | M21: SPECIAL NOTES / SEQUENCE | N21: VENDORS DAILY STATUS REPORT
A22: =IFERROR(VLOOKUP(D22,'Master sheet (Clientes)'!A$6:D$747,2,0)," ") -> NJ | B22: =IFERROR(VLOOKUP(D22,'Master sheet (Clientes)'!A$6:D$747,3,0)," ") -> Greystar | C22: =IFERROR(VLOOKUP(D22,'Master sheet (Clientes)'!A$6:D$747,4,0)," ") -> A-V | D22: The Grand 508 51st St, West New York, NJ 07093 | E22: 407 | F22: 1BDR | G22: Vacant | H22: Paint unit and Unit cleaning at 8:00am Note: Property will provide the paint. | I22: Atlas Javier Santiago | J22: Email | N22: Paint done
A23: =IFERROR(VLOOKUP(D23,'Master sheet (Clientes)'!A$6:D$747,2,0)," ") -> NJ | B23: =IFERROR(VLOOKUP(D23,'Master sheet (Clientes)'!A$6:D$747,3,0)," ") -> Vivmark Residential | C23: =IFERROR(VLOOKUP(D23,'Master sheet (Clientes)'!A$6:D$747,4,0)," ") -> A-V | D23: The Landings at Port Imperial Apartment 4 Ave at Port Imperial, West New York, NJ 07093. | E23: 1101 | F23: 3BDR | G23: Vacant | H23: Paint unit at 8:00 am | I23: Atlas Douglas Espinal | J23: Email | M23: Clean 09/01 | N23: Paint done
A25: State | B25: MANAGEMENT | C25: BC CLERK | D25: BUILDING / ADDRESS | E25: UNIT / AREA | F25: SIZE | G25: WORKSITE STATUS | H25: JOB DESCRIPTION | I25: JOB AWARDED TO: / TECHS QUANTITY: | J25: REQUEST / P.O / WTN / W.O | K25: BC WORK ORDER / BC ESTIMATE | L25: EXTRAS | M25: SPECIAL NOTES / SEQUENCE | N25: VENDORS DAILY STATUS REPORT
A26: =IFERROR(VLOOKUP(D26,'Master sheet (Clientes)'!A$6:D$747,2,0)," ") -> NJ | B26: =IFERROR(VLOOKUP(D26,'Master sheet (Clientes)'!A$6:D$747,3,0)," ") -> Skylight | C26: =IFERROR(VLOOKUP(D26,'Master sheet (Clientes)'!A$6:D$747,4,0)," ") -> N-O | D26: The Sterling 2055 Center Ave, Fort Lee, NJ 07024 | E26: 14A | F26: 1BDR | G26: Vacant | H26: Post Construction cleaning at 8:00am | I26: YL Cleaning | J26: Email | K26: Estimate 16258 | M26: This project is for capital projects and will be paid under the construction budget not the property | N26: Cancelled no longer needed the lceaning was made by the tenant since they moved in on 08/28
A27: =IFERROR(VLOOKUP(D27,'Master sheet (Clientes)'!A$6:D$747,2,0)," ") -> NJ | B27: =IFERROR(VLOOKUP(D27,'Master sheet (Clientes)'!A$6:D$747,3,0)," ") -> Skylight | C27: =IFERROR(VLOOKUP(D27,'Master sheet (Clientes)'!A$6:D$747,4,0)," ") -> N-O | D27: Riello 99 Gorge Rd, Edgewater, NJ 07020 | E27: 1506 | F27: 1BDR | G27: Vacant | H27: Deep Cleaning Unit at 8:00am For access, please call Tim 1 (914) 409-8866 or Chris 917-774-4548 | I27: YL Cleaning | J27: Email | N27: Done
A28: =IFERROR(VLOOKUP(D28,'Master sheet (Clientes)'!A$6:D$747,2,0)," ") -> NJ | B28: =IFERROR(VLOOKUP(D28,'Master sheet (Clientes)'!A$6:D$747,3,0)," ") -> Skylight | C28: =IFERROR(VLOOKUP(D28,'Master sheet (Clientes)'!A$6:D$747,4,0)," ") -> N-O | D28: Riello 99 Gorge Rd, Edgewater, NJ 07020 | E28: 1502 | F28: 1BDR | G28: Vacant | H28: Deep Cleaning Unit at 8:00am For access, please call Tim 1 (914) 409-8866 or Chris 917-774-4548 | I28: YL Cleaning | J28: Email | N28: Done
A29: =IFERROR(VLOOKUP(D29,'Master sheet (Clientes)'!A$6:D$747,2,0)," ") -> NJ | B29: =IFERROR(VLOOKUP(D29,'Master sheet (Clientes)'!A$6:D$747,3,0)," ") -> Skylight | C29: =IFERROR(VLOOKUP(D29,'Master sheet (Clientes)'!A$6:D$747,4,0)," ") -> N-O | D29: Riello 99 Gorge Rd, Edgewater, NJ 07020 | E29: 1503 | F29: 2BDR | G29: Vacant | H29: Deep Cleaning Unit at 8:00am For access, please call Tim 1 (914) 409-8866 or Chris 917-774-4548 | I29: YL Cleaning | J29: Email | N29: Done
A30: =IFERROR(VLOOKUP(D30,'Master sheet (Clientes)'!A$6:D$747,2,0)," ") -> NJ | B30: =IFERROR(VLOOKUP(D30,'Master sheet (Clientes)'!A$6:D$747,3,0)," ") -> Skylight | C30: =IFERROR(VLOOKUP(D30,'Master sheet (Clientes)'!A$6:D$747,4,0)," ") -> N-O | D30: Riello 99 Gorge Rd, Edgewater, NJ 07020 | E30: 1702 | F30: 1BDR | G30: Vacant | H30: Deep Cleaning Unit at 8:00am For access, please call Tim 1 (914) 409-8866 or Chris 917-774-4548 | I30: YL Cleaning | J30: Email | N30: Done
A31: =IFERROR(VLOOKUP(D31,'Master sheet (Clientes)'!A$6:D$747,2,0)," ") -> NJ | B31: =IFERROR(VLOOKUP(D31,'Master sheet (Clientes)'!A$6:D$747,3,0)," ") -> Vivmark Residential | C31: =IFERROR(VLOOKUP(D31,'Master sheet (Clientes)'!A$6:D$747,4,0)," ") -> N-O | D31: Avalon at Edgewater II New Building (Russell). | E31: 104 | F31: 1BDR | G31: Occupeid | H31: Unit Cleaning after repair / Last minute assigned by Carlos | I31: YL Cleaning | J31: Email | N31: Done
A33: State | B33: MANAGEMENT | C33: BC CLERK | D33: BUILDING / ADDRESS | E33: UNIT / AREA | F33: SIZE | G33: WORKSITE STATUS | H33: JOB DESCRIPTION | I33: JOB AWARDED TO: / TECHS QUANTITY: | J33: REQUEST / P.O / WTN / W.O | K33: BC WORK ORDER / BC ESTIMATE | L33: EXTRAS | M33: SPECIAL NOTES / SEQUENCE | N33: VENDORS DAILY STATUS REPORT
A34: =IFERROR(VLOOKUP(D34,'Master sheet (Clientes)'!A$6:D$747,2,0)," ") -> NJ | B34: =IFERROR(VLOOKUP(D34,'Master sheet (Clientes)'!A$6:D$747,3,0)," ") -> Vivmark Residential | C34: =IFERROR(VLOOKUP(D34,'Master sheet (Clientes)'!A$6:D$747,4,0)," ") -> N-O | D34: Avalon at Edgewater II New Building (Russell). | E34: Bike room | H34: Scrape damaged concrete wall refill holes with concrete once dry repaint that area with same color spec. Call Carlos Perez for further instructions | I34: MVC Cleaning | J34: Email | K34: Estimate 16730 | M34: Bike Room / This job can't be mentioned on the final invoice | N34: Done
A35: =IFERROR(VLOOKUP(D35,'Master sheet (Clientes)'!A$6:D$747,2,0)," ") -> NJ | B35: =IFERROR(VLOOKUP(D35,'Master sheet (Clientes)'!A$6:D$747,3,0)," ") -> Vivmark Residential | C35: =IFERROR(VLOOKUP(D35,'Master sheet (Clientes)'!A$6:D$747,4,0)," ") -> N-O | D35: Avalon at Edgewater I Old Building (River Mews). | E35: 419 | G35: Occupied | H35: Inspect and Repair Water leak that might be coming from the skylight - Bc to provide all materials and labor needed to complete the job. For access, please call Christian 201-705-0879 or Alex 201-713-8719 Last minute request | I35: MVC Cleaning | J35: Email | N35: Done
A37: State | B37: MANAGEMENT | C37: BC CLERK | D37: BUILDING / ADDRESS | E37: UNIT / AREA | F37: SIZE | G37: WORKSITE STATUS | H37: MEETING / INSPECTION | I37: EMPLOYEE OR TEAM ASSIGNED | J37: REQUEST / P.O / WTN / W.O | K37: BC WORK ORDER / BC ESTIMATE | L37: EXTRAS | M37: SPECIAL NOTES / SEQUENCE | N37: VENDORS DAILY STATUS REPORT
A38: =IFERROR(VLOOKUP(D38,'Master sheet (Clientes)'!A$6:D$747,2,0)," ") -> NJ | B38: =IFERROR(VLOOKUP(D38,'Master sheet (Clientes)'!A$6:D$747,3,0)," ") -> Vivmark Residential | C38: =IFERROR(VLOOKUP(D38,'Master sheet (Clientes)'!A$6:D$747,4,0)," ") -> N-O | D38: Avalon at Edgewater II New Building (Russell). | E38: 324 | G38: Occupied | H38: Bathtub reglaze NOTE: Please be on tie since this unit is occupied / For access, please call Christian 201-705-0879 or Alex 201-713-8719 | I38: Felix R Santos | J38: Email | N38: Done
A40: State | B40: MANAGEMENT | C40: BC CLERK | D40: BUILDING / ADDRESS | E40: UNIT / AREA | F40: SIZE | G40: WORKSITE STATUS | H40: JOB DESCRIPTION | I40: JOB AWARDED TO: / TECHS QUANTITY: | J40: REQUEST / P.O / WTN / W.O | K40: BC WORK ORDER / BC ESTIMATE | L40: EXTRAS | M40: SPECIAL NOTES / SEQUENCE | N40: VENDORS DAILY STATUS REPORT
A41: =IFERROR(VLOOKUP(D41,'Master sheet (Clientes)'!A$6:D$747,2,0)," ") -> NJ | B41: =IFERROR(VLOOKUP(D41,'Master sheet (Clientes)'!A$6:D$747,3,0)," ") -> Vivmark Residential | C41: =IFERROR(VLOOKUP(D41,'Master sheet (Clientes)'!A$6:D$747,4,0)," ") -> N-O | D41: Avalon at Edgewater II New Building (Russell). | E41: 104 | G41: ??? | H41: Sub-floor repair and carpet padding | I41: Excellent Carpet | J41: Email | N41: Done
D43: SOUTH HOBOKEN "7th Street down" - JERSEY CITY - BAYONNE
D44: JERSEY CITY - BC SUPERVISOR: Carlos Perez (862) 383-3884 cperez@build-care.com - BC RUNNER: Juan Sebastian Salazar (862) 394-6010 jssalazar@build-care.com
A46: State | B46: MANAGEMENT | C46: BC CLERK | D46: BUILDING / ADDRESS | E46: UNIT / AREA | F46: SIZE | G46: WORKSITE STATUS | H46: JOB DESCRIPTION | I46: JOB AWARDED TO: / TECHS QUANTITY: | J46: REQUEST / P.O / WTN / W.O | K46: BC WORK ORDER / BC ESTIMATE | L46: EXTRAS | M46: SPECIAL NOTES / SEQUENCE | N46: VENDORS DAILY STATUS REPORT
A47: =IFERROR(VLOOKUP(D47,'Master sheet (Clientes)'!A$6:D$747,2,0)," ") -> NJ | B47: =IFERROR(VLOOKUP(D47,'Master sheet (Clientes)'!A$6:D$747,3,0)," ") -> RHO | C47: =IFERROR(VLOOKUP(D47,'Master sheet (Clientes)'!A$6:D$747,4,0)," ") -> A-V | D47: Sable 200 Greene Street, Jersey City, NJ 07311. | H47: 1 Daily Handyman service everyday Until Monday 08/31 Please Report to Nate (201) 466-8357 | I47: Sanai Pliability Delfino Cuxil | J47: Email | M47: Extended until Monday 08/31 | N47: Completed
A48: =IFERROR(VLOOKUP(D48,'Master sheet (Clientes)'!A$6:D$747,2,0)," ") -> NJ | B48: =IFERROR(VLOOKUP(D48,'Master sheet (Clientes)'!A$6:D$747,3,0)," ") -> Skylight | C48: =IFERROR(VLOOKUP(D48,'Master sheet (Clientes)'!A$6:D$747,4,0)," ") -> N-O | D48: Grand Adams Apartments 300 Grand St, Hoboken, NJ 07030 | H48: 1 Daily Handyman to work with the maintenance staff 8hrs shift to cover multiple properties under the instructions of the service general manager Upon Arrival Call Orville (646) 984-3306 from 9:00am to 5:00pm Monday to Friday until further notice Starting Tuesday 02/26/2025 | I48: Cuxil Group Eduardo Garcia | J48: Email | M48: until further notice | N48: Continue
A49: =IFERROR(VLOOKUP(D49,'Master sheet (Clientes)'!A$6:D$747,2,0)," ") -> NJ | B49: =IFERROR(VLOOKUP(D49,'Master sheet (Clientes)'!A$6:D$747,3,0)," ") -> Skylight | C49: =IFERROR(VLOOKUP(D49,'Master sheet (Clientes)'!A$6:D$747,4,0)," ") -> N-O | D49: Grand Adams Apartments 300 Grand St, Hoboken, NJ 07030 | H49: 1 Daily handyman for 8hrs shift to assist the property with internal tasks from Monday to Friday until further notice NOTE: Please Report to Christina 973-776-4602 | I49: Cuxil Group Marcos Garcia | J49: Email | M49: until further notice | N49: Continue
A50: =IFERROR(VLOOKUP(D50,'Master sheet (Clientes)'!A$6:D$747,2,0)," ") -> NJ | B50: =IFERROR(VLOOKUP(D50,'Master sheet (Clientes)'!A$6:D$747,3,0)," ") -> Optimum | C50: =IFERROR(VLOOKUP(D50,'Master sheet (Clientes)'!A$6:D$747,4,0)," ") -> A-V | D50: 25 Kensington Ave Jersey City, NJ 07304 | E50: Medical Office Suite #106 | G50: Occupied | H50: Continue Repair all walls / Paint the entire commercial space Color change at 8:30am NOTE: **The reception area, the room with the file cabinet, will not be painted.** / Please contact super Eduardo for access: 551-260-0514 | I50: Sanai Pliability Eddy Cumes / Alexander Polanco | J50: Email | N50: Continue
A52: State | B52: MANAGEMENT | C52: BC CLERK | D52: BUILDING / ADDRESS | E52: UNIT / AREA | F52: SIZE | G52: WORKSITE STATUS | H52: JOB DESCRIPTION | I52: JOB AWARDED TO: / TECHS QUANTITY: | J52: REQUEST / P.O / WTN / W.O | K52: BC WORK ORDER / BC ESTIMATE | L52: EXTRAS | M52: SPECIAL NOTES / SEQUENCE | N52: VENDORS DAILY STATUS REPORT
A53: =IFERROR(VLOOKUP(D53,'Master sheet (Clientes)'!A$6:D$747,2,0)," ") -> NJ | B53: =IFERROR(VLOOKUP(D53,'Master sheet (Clientes)'!A$6:D$747,3,0)," ") -> Rose Associates | C53: =IFERROR(VLOOKUP(D53,'Master sheet (Clientes)'!A$6:D$747,4,0)," ") -> A-V | D53: VYV Apartments North and South 474 Warren St, Jersey City, NJ 07302. | H53: 1 Daily Handyman Service: Provide a full-time daily handyman to assist the property with make-ready orders from 8:00 am to 4:30 pm. 5 Days per week Monday to Friday Starting Monday 08/03/26 to Friday 10/16/2026 | I53: Atlas Alexis Gomez | J53: Email | L53: New management | M53: 5 days per week Until 10/16 | N53: Continue
...

Sheet Tue, Sep 01
A1: BuildCare SCHEDULE TUESDAY, SEPTEMBER 01 / 2026
A3: SUPERVISOR ON CALL NJ: Sebastian Lopez (551) 202-4443 jlopez@build-care.com
A4: CREWS ASSIGNED BY DEFAULT ON CALL: DVM - Atlas Techs / Atlas Cleaning - HG Services
A5: CREWS CONFIRMED BY THE ON CALL: ????
A6: BC MEMBERS OFF/VACATIONS:
D9: STATE OF NEW JERSEY
D11: WATERFRONT AREA (Fort Lee - Edgewater - Cliffside Park - Fairview - North Bergen - West New York - Weehawken - North Hoboken "8th Street Up" )
D12: BC SUPERVISOR: Carlos Perez (862) 383-3884 cperez@build-care.com BC SUPERVISOR/RUNNER: Juan Zapata (551) 202-4443 jzapata@build-care.com
A14: State | B14: MANAGEMENT | C14: BC CLERK | D14: BUILDING / ADDRESS | E14: UNIT / AREA | F14: SIZE | G14: WORKSITE STATUS | H14: JOB DESCRIPTION | I14: JOB AWARDED TO: / TECHS QUANTITY: | J14: REQUEST / P.O / WTN / W.O | K14: BC WORK ORDER / BC ESTIMATE | L14: EXTRAS | M14: SPECIAL NOTES / SEQUENCE | N14: VENDORS DAILY STATUS REPORT
A15: =IFERROR(VLOOKUP(D15,'Master sheet (Clientes)'!A$6:D$747,2,0)," ") -> NJ | B15: =IFERROR(VLOOKUP(D15,'Master sheet (Clientes)'!A$6:D$747,3,0)," ") -> Vivmark Residential | C15: =IFERROR(VLOOKUP(D15,'Master sheet (Clientes)'!A$6:D$747,4,0)," ") -> N-O | D15: Avalon at Edgewater II New Building (Russell). | E15: 104 | F15: 1BDR | G15: Occupeid | H15: Continue Repair openings that were made by other after suffering leak damage -Repairs will be in the coat closet, laundry closet, living room, hallway, bedroom, and bathroom walls. In the bathroom we will have to redo the bathroom tiles area is approximately 8x10 tiles will have to be removed, and sub floor repaired before installing new tiles at 9:00am The building will provide paint Bc to provide all other materials and labor needed to complete the job. For access, please call Christian 201-705-0879 or Alex 201-713-8719 | I15: AJ Canas Solutions Willian Alvarez / Marlon | J15: Email | N15: Continue
A16: =IFERROR(VLOOKUP(D16,'Master sheet (Clientes)'!A$6:D$747,2,0)," ") -> NJ | B16: =IFERROR(VLOOKUP(D16,'Master sheet (Clientes)'!A$6:D$747,3,0)," ") -> Vivmark Residential | C16: =IFERROR(VLOOKUP(D16,'Master sheet (Clientes)'!A$6:D$747,4,0)," ") -> N-O | D16: Avalon at Edgewater II New Building (Russell). | E16: 155 | G16: Occupied | H16: Continue Left side bedroom bathroom tile floor to be demoed, sub floor fixed, install new tiles, and grout area is 9ft x 6ft. at 9am Bc to provide all materials and labor needed to complete the job. For access, please call Christian 201-705-0879 or Alex 201-713-8719 | I16: AJ Canas Solutions Ricardo / Carlos | J16: Email | N16: Continue
A17: =IFERROR(VLOOKUP(D17,'Master sheet (Clientes)'!A$6:D$747,2,0)," ") -> NJ | B17: =IFERROR(VLOOKUP(D17,'Master sheet (Clientes)'!A$6:D$747,3,0)," ") -> Vivmark Residential | C17: =IFERROR(VLOOKUP(D17,'Master sheet (Clientes)'!A$6:D$747,4,0)," ") -> N-O | D17: Avalon at Edgewater II New Building (Russell). | E17: 242 | G17: Occupied | H17: Repair bathroom ceiling from opening made by others at 9am The building will provide the paint. Bc to provide all materials and labor needed to complete the job. For access, please call Christian 201-705-0879 or Alex 201-713-8719 | I17: AJ Canas Solutions Javier | J17: Email | N17: Done
A18: =IFERROR(VLOOKUP(D18,'Master sheet (Clientes)'!A$6:D$747,2,0)," ") -> NJ | B18: =IFERROR(VLOOKUP(D18,'Master sheet (Clientes)'!A$6:D$747,3,0)," ") -> Skylight | C18: =IFERROR(VLOOKUP(D18,'Master sheet (Clientes)'!A$6:D$747,4,0)," ") -> N-O | D18: The Sterling 2055 Center Ave, Fort Lee, NJ 07024 | E18: 5D | G18: Occupied | H18: Repair opening made by others and install missing parquet NOTE: BC to provide plastic drop, spackle, rosin paper, wall paint, blue tape, metal for framing, drywall, primer grip, sanding sponge, floor trim and other materials and labor needed to complete the job. / For access, please call Steve (646) 299-5888 or Jeffery 929-218-9732 | I18: AJ Canas Solutions William dias. | J18: Email | N18: Continue
A20: State | B20: MANAGEMENT | C20: BC CLERK | D20: BUILDING / ADDRESS | E20: UNIT / AREA | F20: SIZE | G20: WORKSITE STATUS | H20: JOB DESCRIPTION | I20: JOB AWARDED TO: / TECHS QUANTITY: | J20: REQUEST / P.O / WTN / W.O | K20: BC WORK ORDER / BC ESTIMATE | L20: EXTRAS | M20: SPECIAL NOTES / SEQUENCE | N20: VENDORS DAILY STATUS REPORT
A21: =IFERROR(VLOOKUP(D21,'Master sheet (Clientes)'!A$6:D$747,2,0)," ") -> NJ | B21: =IFERROR(VLOOKUP(D21,'Master sheet (Clientes)'!A$6:D$747,3,0)," ") -> Skylight | C21: =IFERROR(VLOOKUP(D21,'Master sheet (Clientes)'!A$6:D$747,4,0)," ") -> N-O | D21: Infinity at Edgewater 340 Old River Rd, Edgewater, NJ 07020 | E21: 609 | F21: 1BDR | G21: Vacant | H21: Second Request: Paint Unit (apply scent, including all ceilings; cover carpets and floors) and Unit Cleaning at 8:00am | I21: Atlas Douglas Espinal - Jesus Alvarado | J21: Email | N21: Paint done
A23: State | B23: MANAGEMENT | C23: BC CLERK | D23: BUILDING / ADDRESS | E23: UNIT / AREA | F23: SIZE | G23: WORKSITE STATUS | H23: JOB DESCRIPTION | I23: JOB AWARDED TO: / TECHS QUANTITY: | J23: REQUEST / P.O / WTN / W.O | K23: BC WORK ORDER / BC ESTIMATE | L23: EXTRAS | M23: SPECIAL NOTES / SEQUENCE | N23: VENDORS DAILY STATUS REPORT
A24: =IFERROR(VLOOKUP(D24,'Master sheet (Clientes)'!A$6:D$747,2,0)," ") -> NJ | B24: =IFERROR(VLOOKUP(D24,'Master sheet (Clientes)'!A$6:D$747,3,0)," ") -> No Charge / Courtesy Job | C24: =IFERROR(VLOOKUP(D24,'Master sheet (Clientes)'!A$6:D$747,4,0)," ") -> N/A | D24: 1114 92nd St North Bergen, NJ 07047 | H24: Continue demolish the kitchen countertops on the 1st floor the top row above the ones demolished by mistake including the soffit. | I24: Sanai Pliability Elmer Morales / Delfino Cuxil | J24: Email | M24: No Charge / Courtesy job for Christian Glaser | N24: Continue
A26: State | B26: MANAGEMENT | C26: BC CLERK | D26: BUILDING / ADDRESS | E26: UNIT / AREA | F26: SIZE | G26: WORKSITE STATUS | H26: JOB DESCRIPTION | I26: JOB AWARDED TO: / TECHS QUANTITY: | J26: REQUEST / P.O / WTN / W.O | K26: BC WORK ORDER / BC ESTIMATE | L26: EXTRAS | M26: SPECIAL NOTES / SEQUENCE | N26: VENDORS DAILY STATUS REPORT
A27: =IFERROR(VLOOKUP(D27,'Master sheet (Clientes)'!A$6:D$747,2,0)," ") -> NJ | B27: =IFERROR(VLOOKUP(D27,'Master sheet (Clientes)'!A$6:D$747,3,0)," ") -> Vivmark Residential | C27: =IFERROR(VLOOKUP(D27,'Master sheet (Clientes)'!A$6:D$747,4,0)," ") -> A-V | D27: The Landings at Port Imperial Apartment 4 Ave at Port Imperial, West New York, NJ 07093. | E27: 1101 | F27: 3BDR | G27: Vacant | H27: Unit cleaning at 8:00 am | I27: YL Cleaning | J27: Email | N27: Done
A28: =IFERROR(VLOOKUP(D28,'Master sheet (Clientes)'!A$6:D$747,2,0)," ") -> NJ | B28: =IFERROR(VLOOKUP(D28,'Master sheet (Clientes)'!A$6:D$747,3,0)," ") -> Greystar | C28: =IFERROR(VLOOKUP(D28,'Master sheet (Clientes)'!A$6:D$747,4,0)," ") -> A-V | D28: The Grand 508 51st St, West New York, NJ 07093 | E28: 407 | F28: 1BDR | G28: Vacant | H28: Unit cleaning at 8:00 am | I28: YL Cleaning | J28: Email | N28: Done
A29: =IFERROR(VLOOKUP(D29,'Master sheet (Clientes)'!A$6:D$747,2,0)," ") -> NJ | B29: =IFERROR(VLOOKUP(D29,'Master sheet (Clientes)'!A$6:D$747,3,0)," ") -> Vivmark Residential | C29: =IFERROR(VLOOKUP(D29,'Master sheet (Clientes)'!A$6:D$747,4,0)," ") -> N-O | D29: Avalon at Edgewater II New Building (Russell). | E29: 104 | F29: 1BDR | G29: Occupeid | H29: Unit Cleaning after repair / Last minute assigned by Carlos | I29: YL Cleaning | J29: Email | N29: Done
D31: SOUTH HOBOKEN "7th Street down" - JERSEY CITY - BAYONNE
D32: JERSEY CITY - BC SUPERVISOR: Carlos Perez (862) 383-3884 cperez@build-care.com - BC RUNNER: Juan Sebastian Salazar (862) 394-6010 jssalazar@build-care.com
A34: State | B34: MANAGEMENT | C34: BC CLERK | D34: BUILDING / ADDRESS | E34: UNIT / AREA | F34: SIZE | G34: WORKSITE STATUS | H34: JOB DESCRIPTION | I34: JOB AWARDED TO: / TECHS QUANTITY: | J34: REQUEST / P.O / WTN / W.O | K34: BC WORK ORDER / BC ESTIMATE | L34: EXTRAS | M34: SPECIAL NOTES / SEQUENCE | N34: VENDORS DAILY STATUS REPORT
A35: =IFERROR(VLOOKUP(D35,'Master sheet (Clientes)'!A$6:D$747,2,0)," ") -> NJ | B35: =IFERROR(VLOOKUP(D35,'Master sheet (Clientes)'!A$6:D$747,3,0)," ") -> Skylight | C35: =IFERROR(VLOOKUP(D35,'Master sheet (Clientes)'!A$6:D$747,4,0)," ") -> N-O | D35: Grand Adams Apartments 300 Grand St, Hoboken, NJ 07030 | H35: 1 Daily Handyman to work with the maintenance staff 8hrs shift to cover multiple properties under the instructions of the service general manager Upon Arrival Call Orville (646) 984-3306 from 9:00am to 5:00pm Monday to Friday until further notice Starting Tuesday 02/26/2025 | I35: Cuxil Group Eduardo Garcia | J35: Email | M35: until further notice | N35: Continue
A36: =IFERROR(VLOOKUP(D36,'Master sheet (Clientes)'!A$6:D$747,2,0)," ") -> NJ | B36: =IFERROR(VLOOKUP(D36,'Master sheet (Clientes)'!A$6:D$747,3,0)," ") -> Skylight | C36: =IFERROR(VLOOKUP(D36,'Master sheet (Clientes)'!A$6:D$747,4,0)," ") -> N-O | D36: Grand Adams Apartments 300 Grand St, Hoboken, NJ 07030 | H36: 1 Daily handyman for 8hrs shift to assist the property with internal tasks from Monday to Friday until further notice NOTE: Please Report to Christina 973-776-4602 | I36: Cuxil Group Marcos Garcia | J36: Email | M36: until further notice | N36: Continue
A37: =IFERROR(VLOOKUP(D37,'Master sheet (Clientes)'!A$6:D$747,2,0)," ") -> NJ | B37: =IFERROR(VLOOKUP(D37,'Master sheet (Clientes)'!A$6:D$747,3,0)," ") -> Optimum | C37: =IFERROR(VLOOKUP(D37,'Master sheet (Clientes)'!A$6:D$747,4,0)," ") -> A-V | D37: 25 Kensington Ave Jersey City, NJ 07304 | E37: Medical Office Suite #106 | G37: Occupied | H37: Continue Repair all walls / Paint the entire commercial space Color change at 8:30am NOTE: **The reception area, the room with the file cabinet, will not be painted.** / Please contact super Eduardo for access: 551-260-0514 | I37: Sanai Pliability Eddy Cumes / Alexander Polanco | J37: Email | N37: Done
A39: State | B39: MANAGEMENT | C39: BC CLERK | D39: BUILDING / ADDRESS | E39: UNIT / AREA | F39: SIZE | G39: WORKSITE STATUS | H39: JOB DESCRIPTION | I39: JOB AWARDED TO: / TECHS QUANTITY: | J39: REQUEST / P.O / WTN / W.O | K39: BC WORK ORDER / BC ESTIMATE | L39: EXTRAS | M39: SPECIAL NOTES / SEQUENCE | N39: VENDORS DAILY STATUS REPORT
A40: =IFERROR(VLOOKUP(D40,'Master sheet (Clientes)'!A$6:D$747,2,0)," ") -> NJ | B40: =IFERROR(VLOOKUP(D40,'Master sheet (Clientes)'!A$6:D$747,3,0)," ") -> Rose Associates | C40: =IFERROR(VLOOKUP(D40,'Master sheet (Clientes)'!A$6:D$747,4,0)," ") -> A-V | D40: VYV Apartments North and South 474 Warren St, Jersey City, NJ 07302. | H40: 1 Daily Handyman Service: Provide a full-time daily handyman to assist the property with make-ready orders from 8:00 am to 4:30 pm. 5 Days per week Monday to Friday Starting Monday 08/03/26 to Friday 10/16/2026 | I40: Atlas Alexis Gomez | J40: Email | M40: 5 days per week Until 10/16 | N40: Continue
A41: =IFERROR(VLOOKUP(D41,'Master sheet (Clientes)'!A$6:D$747,2,0)," ") -> NJ | B41: =IFERROR(VLOOKUP(D41,'Master sheet (Clientes)'!A$6:D$747,3,0)," ") -> Greystar | C41: =IFERROR(VLOOKUP(D41,'Master sheet (Clientes)'!A$6:D$747,4,0)," ") -> A-V | D41: Liberty Bay Club Apartments 190 W 54th St, Bayonne, NJ 07002 | E41: 239 | F41: 2BDR | G41: Vacant | H41: Paint unit and cleaning at 8:0am Note: Property will provide the paint. | I41: Atlas Douglas Espinal - Jesus Alvarado | J41: Email | N41: Paint done
A42: =IFERROR(VLOOKUP(D42,'Master sheet (Clientes)'!A$6:D$747,2,0)," ") -> NJ | B42: =IFERROR(VLOOKUP(D42,'Master sheet (Clientes)'!A$6:D$747,3,0)," ") -> Greystar | C42: =IFERROR(VLOOKUP(D42,'Master sheet (Clientes)'!A$6:D$747,4,0)," ") -> A-V | D42: Liberty Bay Club Apartments 190 W 54th St, Bayonne, NJ 07002 | E42: 147 | F42: 1BDR | G42: Vacant | H42: Paint unit and cleaning at 8:0am Note: Property will provide the paint. | I42: Atlas Douglas Espinal - Jesus Alvarado | J42: Email | N42: Paint done
A43: =IFERROR(VLOOKUP(D43,'Master sheet (Clientes)'!A$6:D$747,2,0)," ") -> NJ | B43: =IFERROR(VLOOKUP(D43,'Master sheet (Clientes)'!A$6:D$747,3,0)," ") -> Vivmark Residential | C43: =IFERROR(VLOOKUP(D43,'Master sheet (Clientes)'!A$6:D$747,4,0)," ") -> A-V | D43: Hudson Point Apartments 131 Dudley St Ste Off, Jersey City, NJ 07302. | E43: 415 | F43: 1BDR | G43: Vacant | H43: Paint unit and Cleaning same day at 8:00 am NOTE: The building will provide the Paint For access, Please call Colin 1(973) 255-8682 or Eli 917-442-0088 | I43: Atlas Javier Santiago | J43: Paint WTN 86508201 | N43: Paint done
A44: =IFERROR(VLOOKUP(D44,'Master sheet (Clientes)'!A$6:D$747,2,0)," ") -> NJ | B44: =IFERROR(VLOOKUP(D44,'Master sheet (Clientes)'!A$6:D$747,3,0)," ") -> Vivmark Residential | C44: =IFERROR(VLOOKUP(D44,'Master sheet (Clientes)'!A$6:D$747,4,0)," ") -> A-V | D44: 70 Greene Apartments 70 Greene St, Jersey City, NJ 07302. | E44: 3107 | F44: 1BDR | G44: Vacant | H44: Paint unit at 8:00 am | I44: Atlas Elder Velasquez | J44: WTN 86388866 | N44: Paint done
A46: State | B46: MANAGEMENT | C46: BC CLERK | D46: BUILDING / ADDRESS | E46: UNIT / AREA | F46: SIZE | G46: WORKSITE STATUS | H46: JOB DESCRIPTION | I46: JOB AWARDED TO: / TECHS QUANTITY: | J46: REQUEST / P.O / WTN / W.O | K46: BC WORK ORDER / BC ESTIMATE | L46: EXTRAS | M46: SPECIAL NOTES / SEQUENCE | N46: VENDORS DAILY STATUS REPORT
A47: =IFERROR(VLOOKUP(D47,'Master sheet (Clientes)'!A$6:D$747,2,0)," ") -> NJ | B47: =IFERROR(VLOOKUP(D47,'Master sheet (Clientes)'!A$6:D$747,3,0)," ") -> Bozzuto | C47: =IFERROR(VLOOKUP(D47,'Master sheet (Clientes)'!A$6:D$747,4,0)," ") -> N-O | D47: Vantage Collection 1 Park View Ave, Jersey City, NJ 07302 | E47: PH38 | G47: Occupied | H47: Continue Door and shelving Installation: Remove and demo the existing pocket door, including the frame. \ Perform all necessary repairs required to install a Buildcare-provided 36" x 80" metal frame. \ Install the property-provided door. \ Install Buildcare-provided door hardware. \ Paint the wall, door, and frame using property-provided paint. \ Install the Buildcare-provided closet shelving system that was previously removed by the client. | I47: Alluda Anibal Yojero / Misael Yojero | J47: Email | K47: Estimate 15942 | M47: 4 Handys quoted | N47: Done
A49: State | B49: MANAGEMENT | C49: BC CLERK | D49: BUILDING / ADDRESS | E49: UNIT / AREA | F49: SIZE | G49: WORKSITE STATUS | H49: JOB DESCRIPTION | I49: JOB AWARDED TO: / TECHS QUANTITY: | J49: REQUEST / P.O / WTN / W.O | K49: BC WORK ORDER / BC ESTIMATE | L49: EXTRAS | M49: SPECIAL NOTES / SEQUENCE | N49: VENDORS DAILY STATUS REPORT
A50: =IFERROR(VLOOKUP(D50,'Master sheet (Clientes)'!A$6:D$747,2,0)," ") -> NJ | B50: =IFERROR(VLOOKUP(D50,'Master sheet (Clientes)'!A$6:D$747,3,0)," ") -> Bozzuto | C50: =IFERROR(VLOOKUP(D50,'Master sheet (Clientes)'!A$6:D$747,4,0)," ") -> N-O | D50: Birch House 49 Fisk St, Jersey City, NJ 07305 | E50: 102 | F50: 1BDR | G50: Vacant | H50: Paint unit and Same-day cleaning at 8:00 am | I50: DVM Celestino Luc | J50: Email | M50: Same-day clean | N50: Paint done
A51: =IFERROR(VLOOKUP(D51,'Master sheet (Clientes)'!A$6:D$747,2,0)," ") -> NJ | B51: =IFERROR(VLOOKUP(D51,'Master sheet (Clientes)'!A$6:D$747,3,0)," ") -> Greystar | C51: =IFERROR(VLOOKUP(D51,'Master sheet (Clientes)'!A$6:D$747,4,0)," ") -> A-V | D51: Liberty Bay Club Apartments 190 W 54th St, Bayonne, NJ 07002 | E51: 109 | F51: 1BDR | G51: Vacant | H51: Paint unit and cleaning at 8:0am Note: Property will provide the paint. | I51: DVM Ignacio Luc | J51: Email | N51: Paint done
A52: =IFERROR(VLOOKUP(D52,'Master sheet (Clientes)'!A$6:D$747,2,0)," ") -> NJ | B52: =IFERROR(VLOOKUP(D52,'Master sheet (Clientes)'!A$6:D$747,3,0)," ") -> Greystar | C52: =IFERROR(VLOOKUP(D52,'Master sheet (Clientes)'!A$6:D$747,4,0)," ") -> A-V | D52: The Greyson 25 Cottage St Jersey City, NJ 07306 | E52: 604 | G52: Occupied | H52: Remove base board and Cut drywall 1’x4’ in kitchen area. - Install new drywall and insulation. - Tape, spackle, sand, prime, and paint repaired area.at 9:00 am For access call Raul:+1 (551) 556-8864 | I52: DVM Angel Davila | J52: Email | M52: Note: we only provide the easy sand 20, property provides all materials and paint. | N52: Done
A53: =IFERROR(VLOOKUP(D53,'Master sheet (Clientes)'!A$6:D$747,2,0)," ") -> NJ | B53: =IFERROR(VLOOKUP(D53,'Master sheet (Clientes)'!A$6:D$747,3,0)," ") -> Vivmark Residential | C53: =IFERROR(VLOOKUP(D53,'Master sheet (Clientes)'!A$6:D$747,4,0)," ") -> A-V | D53: 70 Greene Apartments 70 Greene St, Jersey City, NJ 07302. | E53: 4104 | F53: 3BDR | G53: Vacant | H53: Paint unit at 8:00 am NOTE: For access, please call Jonathan 862-387-9993 or Danny 646-508-3402 | I53: DVM Marvin Cumes | J53: WTN Pending | M53: Clean 09/03 | N53: Paint done
...

Sheet Wed, Sep 02
A1: BuildCare SCHEDULE WEDNESDAY, SEPTEMBER 02 / 2026
A3: SUPERVISOR ON CALL NJ: Sebastian Lopez (551) 202-4443 jlopez@build-care.com
A4: CREWS ASSIGNED BY DEFAULT ON CALL: DVM - Atlas Techs / Atlas Cleaning - HG Services
A5: CREWS CONFIRMED BY THE ON CALL: ????
A6: BC MEMBERS OFF/VACATIONS:
D9: STATE OF NEW JERSEY
D11: WATERFRONT AREA (Fort Lee - Edgewater - Cliffside Park - Fairview - North Bergen - West New York - Weehawken - North Hoboken "8th Street Up" )
D12: BC SUPERVISOR: Carlos Perez (862) 383-3884 cperez@build-care.com BC SUPERVISOR/RUNNER: Juan Zapata (551) 202-4443 jzapata@build-care.com
A14: State | B14: MANAGEMENT (Inmobiliaria) | C14: BC CLERK (Persona de Buildcare que hace la factura) | D14: BUILDING / ADDRESS (Nombre y dirección del edificio) | E14: UNIT / AREA (número apartamento - área edificio) | F14: SIZE (tamaño del apartamento) | G14: WORKSITE STATUS (Estado del inmueble) | H14: JOB DESCRIPTION | I14: JOB AWARDED TO: / TECHS QUANTITY: (Nombre de la compañía y trabajador de la compañía) | J14: REQUEST / P.O / WTN / W.O (Por dónde se pidió) | K14: BC WORK ORDER / BC ESTIMATE (Cotizaciones) | L14: EXTRAS | M14: SPECIAL NOTES / SEQUENCE | N14: VENDORS DAILY STATUS REPORT (Continúa o no el trabajo)
A15: =IFERROR(VLOOKUP(D15,'Master sheet (Clientes)'!A$6:D$747,2,0)," ") -> NJ | B15: =IFERROR(VLOOKUP(D15,'Master sheet (Clientes)'!A$6:D$747,3,0)," ") -> Vivmark Residential | C15: =IFERROR(VLOOKUP(D15,'Master sheet (Clientes)'!A$6:D$747,4,0)," ") -> N-O | D15: Avalon at Edgewater II New Building (Russell). | E15: 104 | F15: 1BDR | G15: Occupeid | H15: Continue Repair openings that were made by other after suffering leak damage -Repairs will be in the coat closet, laundry closet, living room, hallway, bedroom, and bathroom walls. In the bathroom we will have to redo the bathroom tiles area is approximately 8x10 tiles will have to be removed, and sub floor repaired before installing new tiles at 9:00am The building will provide paint Bc to provide all other materials and labor needed to complete the job. For access, please call Christian 201-705-0879 or Alex 201-713-8719 | I15: AJ Canas Solutions Ricardo Willian Alvares. | J15: Email | N15: Continue
A16: =IFERROR(VLOOKUP(D16,'Master sheet (Clientes)'!A$6:D$747,2,0)," ") -> NJ | B16: =IFERROR(VLOOKUP(D16,'Master sheet (Clientes)'!A$6:D$747,3,0)," ") -> Vivmark Residential | C16: =IFERROR(VLOOKUP(D16,'Master sheet (Clientes)'!A$6:D$747,4,0)," ") -> N-O | D16: Avalon at Edgewater II New Building (Russell). | E16: 155 | G16: Occupied | H16: Continue Left side bedroom bathroom tile floor to be demoed, sub floor fixed, install new tiles, and grout area is 9ft x 6ft. at 9am Bc to provide all materials and labor needed to complete the job. For access, please call Christian 201-705-0879 or Alex 201-713-8719 | I16: AJ Canas Solutions Vinicio / Carlos | J16: Email | N16: Continue
A17: =IFERROR(VLOOKUP(D17,'Master sheet (Clientes)'!A$6:D$747,2,0)," ") -> NJ | B17: =IFERROR(VLOOKUP(D17,'Master sheet (Clientes)'!A$6:D$747,3,0)," ") -> Skylight | C17: =IFERROR(VLOOKUP(D17,'Master sheet (Clientes)'!A$6:D$747,4,0)," ") -> N-O | D17: The Sterling 2055 Center Ave, Fort Lee, NJ 07024 | E17: 5D | G17: Occupied | H17: Continue Repair opening made by others and install missing parquet NOTE: BC to provide plastic drop, spackle, rosin paper, wall paint, blue tape, metal for framing, drywall, primer grip, sanding sponge, floor trim and other materials and labor needed to complete the job. / For access, please call Steve (646) 299-5888 or Jeffery 929-218-9732 | I17: AJ Canas Solutions Alberto | J17: Email | N17: Done
A18: =IFERROR(VLOOKUP(D18,'Master sheet (Clientes)'!A$6:D$747,2,0)," ") -> NJ | B18: =IFERROR(VLOOKUP(D18,'Master sheet (Clientes)'!A$6:D$747,3,0)," ") -> Vivmark Residential | C18: =IFERROR(VLOOKUP(D18,'Master sheet (Clientes)'!A$6:D$747,4,0)," ") -> N-O | D18: Avalon at Edgewater I Old Building (River Mews). | E18: 426 | G18: Occupied | H18: Continue Make opening in guest bedroom 3x3 to reinstall loose Hvac vent, close opening, spackle, sand and paint NOTE: Bc to provide carpet film, plastic drop, spackle, mesh tape, trash bags, sanding sponge, blue tape and all other materials and labor needed to complete the job. / For access, please call Christian 201-705-0879 or Alex 201-713-8719 update the scope of work. Two more openings of 2x4 were required to see where ducts weren't connected. After the ducts were taped with duct tape, there still wasn't air flow. The building asked to please just temporarily close openings so they can do their own investigation tomorrow to see where the problem is. Once they determine and fix it, they will let us know so we can close all openings properly. | I18: AJ Canas Solutions javier | J18: Email | N18: Done
A19: =IFERROR(VLOOKUP(D19,'Master sheet (Clientes)'!A$6:D$747,2,0)," ") -> NJ | B19: =IFERROR(VLOOKUP(D19,'Master sheet (Clientes)'!A$6:D$747,3,0)," ") -> Skylight | C19: =IFERROR(VLOOKUP(D19,'Master sheet (Clientes)'!A$6:D$747,4,0)," ") -> N-O | D19: Riello 99 Gorge Rd, Edgewater, NJ 07020 | E19: 801 | F19: 1BDR | G19: Vacant | H19: Paint unit and cleaning at 8:00am | I19: AJ Canas Solutions William Diaz | J19: Email | N19: Done
A21: State | B21: MANAGEMENT | C21: BC CLERK | D21: BUILDING / ADDRESS | E21: UNIT / AREA | F21: SIZE | G21: WORKSITE STATUS | H21: JOB DESCRIPTION | I21: JOB AWARDED TO: / TECHS QUANTITY: | J21: REQUEST / P.O / WTN / W.O | K21: BC WORK ORDER / BC ESTIMATE | L21: EXTRAS | M21: SPECIAL NOTES / SEQUENCE | N21: VENDORS DAILY STATUS REPORT
A22: =IFERROR(VLOOKUP(D22,'Master sheet (Clientes)'!A$6:D$747,2,0)," ") -> NJ | B22: =IFERROR(VLOOKUP(D22,'Master sheet (Clientes)'!A$6:D$747,3,0)," ") -> Skylight | C22: =IFERROR(VLOOKUP(D22,'Master sheet (Clientes)'!A$6:D$747,4,0)," ") -> N-O | D22: Infinity at Edgewater 340 Old River Rd, Edgewater, NJ 07020 | E22: 523 | F22: 1BDR | G22: Vacant | H22: Paint Unit (Remove and re-install cover plates / Protect all floors/carpets) at 9:00am Note: BC provides the paint, Call Enrique for access: +1 (646) 984-3300 | I22: Atlas Armando Gaona | J22: Email | M22: Carpet / Clean | N22: Paint done
A23: =IFERROR(VLOOKUP(D23,'Master sheet (Clientes)'!A$6:D$747,2,0)," ") -> NJ | B23: =IFERROR(VLOOKUP(D23,'Master sheet (Clientes)'!A$6:D$747,3,0)," ") -> Vivmark Residential | C23: =IFERROR(VLOOKUP(D23,'Master sheet (Clientes)'!A$6:D$747,4,0)," ") -> N-O | D23: Avalon Hoboken 800 Madison St, Hoboken, NJ 07030. | E23: 630 | F23: 2BDR | G23: Occupied | H23: Paint unit at 8:00 am | I23: Atlas Douglas Espinal | J23: PO-1543976 | N23: Done
A25: State | B25: MANAGEMENT | C25: BC CLERK | D25: BUILDING / ADDRESS | E25: UNIT / AREA | F25: SIZE | G25: WORKSITE STATUS | H25: JOB DESCRIPTION | I25: JOB AWARDED TO: / TECHS QUANTITY: | J25: REQUEST / P.O / WTN / W.O | K25: BC WORK ORDER / BC ESTIMATE | L25: EXTRAS | M25: SPECIAL NOTES / SEQUENCE | N25: VENDORS DAILY STATUS REPORT
A26: =IFERROR(VLOOKUP(D26,'Master sheet (Clientes)'!A$6:D$747,2,0)," ") -> NJ | B26: =IFERROR(VLOOKUP(D26,'Master sheet (Clientes)'!A$6:D$747,3,0)," ") -> No Charge / Courtesy Job | C26: =IFERROR(VLOOKUP(D26,'Master sheet (Clientes)'!A$6:D$747,4,0)," ") -> N/A | D26: 1114 92nd St North Bergen, NJ 07047 | H26: Continue 2 techs to install drywall. Spackle and sand | I26: Sanai Pliability Elmer Morales / Santiago Chanchavac | J26: Email | M26: No Charge / Courtesy job for Christian Glaser | N26: Continue Friday
A28: State | B28: MANAGEMENT | C28: BC CLERK | D28: BUILDING / ADDRESS | E28: UNIT / AREA | F28: SIZE | G28: WORKSITE STATUS | H28: JOB DESCRIPTION | I28: JOB AWARDED TO: / TECHS QUANTITY: | J28: REQUEST / P.O / WTN / W.O | K28: BC WORK ORDER / BC ESTIMATE | L28: EXTRAS | M28: SPECIAL NOTES / SEQUENCE | N28: VENDORS DAILY STATUS REPORT
A29: =IFERROR(VLOOKUP(D29,'Master sheet (Clientes)'!A$6:D$747,2,0)," ") -> NJ | B29: =IFERROR(VLOOKUP(D29,'Master sheet (Clientes)'!A$6:D$747,3,0)," ") -> Vivmark Residential | C29: =IFERROR(VLOOKUP(D29,'Master sheet (Clientes)'!A$6:D$747,4,0)," ") -> A-V | D29: The Rivington Apartments 1130 Grand St, Hoboken, NJ 07030. | E29: SG 505 | G29: Occupied | H29: Replace the kitchen kick plate - 5"x16' - 1/8" thickness - Build care provides the new kick plate Hallway vinyl floor replacement 1 board replacement Build care provides the new vinyl floor.at 9:00 am For access call Emilio:+1 (917) 971-4114 | I29: M&J Flooring | J29: Email | N29: Done
A30: =IFERROR(VLOOKUP(D30,'Master sheet (Clientes)'!A$6:D$747,2,0)," ") -> NJ | B30: =IFERROR(VLOOKUP(D30,'Master sheet (Clientes)'!A$6:D$747,3,0)," ") -> Vivmark Residential | C30: =IFERROR(VLOOKUP(D30,'Master sheet (Clientes)'!A$6:D$747,4,0)," ") -> A-V | D30: The Rivington Apartments 1130 Grand St, Hoboken, NJ 07030. | E30: SG 205 | G30: Occupied | H30: Replace kitchen transition molding. at 9:00am Build care provides the molding. | I30: M&J Flooring | J30: Email | N30: Done
A31: =IFERROR(VLOOKUP(D31,'Master sheet (Clientes)'!A$6:D$747,2,0)," ") -> NJ | B31: =IFERROR(VLOOKUP(D31,'Master sheet (Clientes)'!A$6:D$747,3,0)," ") -> Vivmark Residential | C31: =IFERROR(VLOOKUP(D31,'Master sheet (Clientes)'!A$6:D$747,4,0)," ") -> A-V | D31: The Rivington Apartments 1130 Grand St, Hoboken, NJ 07030. | E31: NG 608 | G31: Occupied | H31: Floor repair Last minute request - assigned by property | I31: M&J Flooring | J31: Email pending Roberto | N31: Done
A32: =IFERROR(VLOOKUP(D32,'Master sheet (Clientes)'!A$6:D$747,2,0)," ") -> NJ | B32: =IFERROR(VLOOKUP(D32,'Master sheet (Clientes)'!A$6:D$747,3,0)," ") -> Vivmark Residential | C32: =IFERROR(VLOOKUP(D32,'Master sheet (Clientes)'!A$6:D$747,4,0)," ") -> A-V | D32: The Rivington Apartments 1130 Grand St, Hoboken, NJ 07030. | E32: NG 207 | G32: Occupied | H32: Floor repair Last minute request - assigned by property | I32: M&J Flooring | J32: Email pending Roberto | N32: Done
A34: State | B34: MANAGEMENT | C34: BC CLERK | D34: BUILDING / ADDRESS | E34: UNIT / AREA | F34: SIZE | G34: WORKSITE STATUS | H34: JOB DESCRIPTION | I34: JOB AWARDED TO: / TECHS QUANTITY: | J34: REQUEST / P.O / WTN / W.O | K34: BC WORK ORDER / BC ESTIMATE | L34: EXTRAS | M34: SPECIAL NOTES / SEQUENCE | N34: VENDORS DAILY STATUS REPORT
A35: =IFERROR(VLOOKUP(D35,'Master sheet (Clientes)'!A$6:D$747,2,0)," ") -> NJ | B35: =IFERROR(VLOOKUP(D35,'Master sheet (Clientes)'!A$6:D$747,3,0)," ") -> Vivmark Residential | C35: =IFERROR(VLOOKUP(D35,'Master sheet (Clientes)'!A$6:D$747,4,0)," ") -> A-V | D35: The Rivington Apartments 1130 Grand St, Hoboken, NJ 07030. | E35: SG 310 | F35: 2BDR | G35: Vacant | H35: Unit Cleaning at 8:00 am | I35: YL Cleaning | J35: Email | N35: Done
A36: =IFERROR(VLOOKUP(D36,'Master sheet (Clientes)'!A$6:D$747,2,0)," ") -> NJ | B36: =IFERROR(VLOOKUP(D36,'Master sheet (Clientes)'!A$6:D$747,3,0)," ") -> Post Brothers | C36: =IFERROR(VLOOKUP(D36,'Master sheet (Clientes)'!A$6:D$747,4,0)," ") -> A-V | D36: The Duchess 7601 River Rd, North Bergen, NJ 07047 | E36: 1222 | F36: 2BDR | G36: Vacant | H36: Unit Cleaning at 8:00 am | I36: YL Cleaning | J36: Email | N36: Done
A37: =IFERROR(VLOOKUP(D37,'Master sheet (Clientes)'!A$6:D$747,2,0)," ") -> NJ | B37: =IFERROR(VLOOKUP(D37,'Master sheet (Clientes)'!A$6:D$747,3,0)," ") -> Skylight | C37: =IFERROR(VLOOKUP(D37,'Master sheet (Clientes)'!A$6:D$747,4,0)," ") -> N-O | D37: Infinity at Edgewater 340 Old River Rd, Edgewater, NJ 07020 | E37: 609 | F37: 1BDR | G37: Vacant | H37: Unit Cleaning at 8:00am | I37: YL Cleaning | J37: Email | N37: Done
A38: =IFERROR(VLOOKUP(D38,'Master sheet (Clientes)'!A$6:D$747,2,0)," ") -> NJ | B38: =IFERROR(VLOOKUP(D38,'Master sheet (Clientes)'!A$6:D$747,3,0)," ") -> Vivmark Residential | C38: =IFERROR(VLOOKUP(D38,'Master sheet (Clientes)'!A$6:D$747,4,0)," ") -> N-O | D38: Avalon at Edgewater II New Building (Russell). | E38: 104 | F38: 1BDR | G38: Occupeid | H38: Unit Cleaning after repair after 2pm | I38: YL Cleaning | J38: Email | N38: Done
A39: =IFERROR(VLOOKUP(D39,'Master sheet (Clientes)'!A$6:D$747,2,0)," ") -> NJ | B39: =IFERROR(VLOOKUP(D39,'Master sheet (Clientes)'!A$6:D$747,3,0)," ") -> Vivmark Residential | C39: =IFERROR(VLOOKUP(D39,'Master sheet (Clientes)'!A$6:D$747,4,0)," ") -> N-O | D39: Avalon at Edgewater II New Building (Russell). | E39: 155 | G39: Occupied | H39: Unit Cleaning after repair after 2pm / Last minute request assigned by Carlos Perez | I39: YL Cleaning | J39: Email | M39: Clean 09/02 and 09/03 | N39: Cancelled by Tenant
D41: SOUTH HOBOKEN "7th Street down" - JERSEY CITY - BAYONNE
D42: JERSEY CITY - BC SUPERVISOR: Carlos Perez (862) 383-3884 cperez@build-care.com - BC RUNNER: Juan Sebastian Salazar (862) 394-6010 jssalazar@build-care.com
A44: State | B44: MANAGEMENT | C44: BC CLERK | D44: BUILDING / ADDRESS | E44: UNIT / AREA | F44: SIZE | G44: WORKSITE STATUS | H44: JOB DESCRIPTION | I44: JOB AWARDED TO: / TECHS QUANTITY: | J44: REQUEST / P.O / WTN / W.O | K44: BC WORK ORDER / BC ESTIMATE | L44: EXTRAS | M44: SPECIAL NOTES / SEQUENCE | N44: VENDORS DAILY STATUS REPORT
A45: =IFERROR(VLOOKUP(D45,'Master sheet (Clientes)'!A$6:D$747,2,0)," ") -> NJ | B45: =IFERROR(VLOOKUP(D45,'Master sheet (Clientes)'!A$6:D$747,3,0)," ") -> Skylight | C45: =IFERROR(VLOOKUP(D45,'Master sheet (Clientes)'!A$6:D$747,4,0)," ") -> N-O | D45: Grand Adams Apartments 300 Grand St, Hoboken, NJ 07030 | H45: 1 Daily Handyman to work with the maintenance staff 8hrs shift to cover multiple properties under the instructions of the service general manager Upon Arrival Call Orville (646) 984-3306 from 9:00am to 5:00pm Monday to Friday until further notice Starting Tuesday 02/26/2025 | I45: Cuxil Group Eduardo Garcia | J45: Email | M45: until further notice | N45: Continue
A46: =IFERROR(VLOOKUP(D46,'Master sheet (Clientes)'!A$6:D$747,2,0)," ") -> NJ | B46: =IFERROR(VLOOKUP(D46,'Master sheet (Clientes)'!A$6:D$747,3,0)," ") -> Skylight | C46: =IFERROR(VLOOKUP(D46,'Master sheet (Clientes)'!A$6:D$747,4,0)," ") -> N-O | D46: Grand Adams Apartments 300 Grand St, Hoboken, NJ 07030 | H46: 1 Daily handyman for 8hrs shift to assist the property with internal tasks from Monday to Friday until further notice NOTE: Please Report to Christina 973-776-4602 | I46: Cuxil Group Marcos Garcia | J46: Email | M46: until further notice | N46: Continue
A47: =IFERROR(VLOOKUP(D47,'Master sheet (Clientes)'!A$6:D$747,2,0)," ") -> NJ | B47: =IFERROR(VLOOKUP(D47,'Master sheet (Clientes)'!A$6:D$747,3,0)," ") -> RHO | C47: =IFERROR(VLOOKUP(D47,'Master sheet (Clientes)'!A$6:D$747,4,0)," ") -> A-V | D47: Sable 200 Greene Street, Jersey City, NJ 07311. | H47: 1 Daily Handyman service from Wednesday 09/02/2026 trough Sunday 09/06/2026 Please Report to Nate (201) 466-8357 | I47: Sanai Pliability Delfino Cuxil | J47: Email | M47: Extended until Sunday 09/06 | N47: Continue
A49: State | B49: MANAGEMENT | C49: BC CLERK | D49: BUILDING / ADDRESS | E49: UNIT / AREA | F49: SIZE | G49: WORKSITE STATUS | H49: JOB DESCRIPTION | I49: JOB AWARDED TO: / TECHS QUANTITY: | J49: REQUEST / P.O / WTN / W.O | K49: BC WORK ORDER / BC ESTIMATE | L49: EXTRAS | M49: SPECIAL NOTES / SEQUENCE | N49: VENDORS DAILY STATUS REPORT
A50: =IFERROR(VLOOKUP(D50,'Master sheet (Clientes)'!A$6:D$747,2,0)," ") -> NJ | B50: =IFERROR(VLOOKUP(D50,'Master sheet (Clientes)'!A$6:D$747,3,0)," ") -> Rose Associates | C50: =IFERROR(VLOOKUP(D50,'Master sheet (Clientes)'!A$6:D$747,4,0)," ") -> A-V | D50: VYV Apartments North and South 474 Warren St, Jersey City, NJ 07302. | H50: 1 Daily Handyman Service: Provide a full-time daily handyman to assist the property with make-ready orders from 8:00 am to 4:30 pm. 5 Days per week Monday to Friday Starting Monday 08/03/26 to Friday 10/16/2026 | I50: Atlas Alexis Gomez | J50: Email | M50: 5 days per week Until 10/16 | N50: Continue
A51: =IFERROR(VLOOKUP(D51,'Master sheet (Clientes)'!A$6:D$747,2,0)," ") -> NJ | B51: =IFERROR(VLOOKUP(D51,'Master sheet (Clientes)'!A$6:D$747,3,0)," ") -> Vivmark Residential | C51: =IFERROR(VLOOKUP(D51,'Master sheet (Clientes)'!A$6:D$747,4,0)," ") -> A-V | D51: 70 Greene Apartments 70 Greene St, Jersey City, NJ 07302. | H51: Daily Painter at 8am please report to Jonathan 862-387-9993 | I51: Atlas Javier Santiago | J51: WTN Pending | N51: Done
A52: =IFERROR(VLOOKUP(D52,'Master sheet (Clientes)'!A$6:D$747,2,0)," ") -> NJ | B52: =IFERROR(VLOOKUP(D52,'Master sheet (Clientes)'!A$6:D$747,3,0)," ") -> Dalan Management | C52: =IFERROR(VLOOKUP(D52,'Master sheet (Clientes)'!A$6:D$747,4,0)," ") -> N-O | D52: The Lively Apartments 321 Warren St, Jersey City, NJ 07302 | E52: 1611 | F52: Studio | G52: Vacant | H52: Paint unit and cleaning at 8:00am The building will provide the paint Please call Kyle for access (551) 208-2742 | I52: Atlas Elder Velasquez | J52: Email | N52: Paint done
...

Sheet Thu, Sep 03
A1: BuildCare SCHEDULE THURSDAY, SEPTEMBER 03 / 2026
A3: SUPERVISOR ON CALL NJ: Sebastian Lopez (551) 202-4443 jlopez@build-care.com
A4: CREWS ASSIGNED BY DEFAULT ON CALL: DVM - Atlas Techs / Atlas Cleaning - HG Services
A5: CREWS CONFIRMED BY THE ON CALL: ????
A6: BC MEMBERS OFF/VACATIONS:
D9: STATE OF NEW JERSEY
D11: WATERFRONT AREA (Fort Lee - Edgewater - Cliffside Park - Fairview - North Bergen - West New York - Weehawken - North Hoboken "8th Street Up" )
D12: BC SUPERVISOR: Carlos Perez (862) 383-3884 cperez@build-care.com BC SUPERVISOR/RUNNER: Juan Zapata (551) 202-4443 jzapata@build-care.com
A14: State | B14: MANAGEMENT | C14: BC CLERK | D14: BUILDING / ADDRESS | E14: UNIT / AREA | F14: SIZE | G14: WORKSITE STATUS | H14: JOB DESCRIPTION | I14: JOB AWARDED TO: / TECHS QUANTITY: | J14: REQUEST / P.O / WTN / W.O | K14: BC WORK ORDER / BC ESTIMATE | L14: EXTRAS | M14: SPECIAL NOTES / SEQUENCE | N14: VENDORS DAILY STATUS REPORT
A15: =IFERROR(VLOOKUP(D15,'Master sheet (Clientes)'!A$6:D$747,2,0)," ") -> NJ | B15: =IFERROR(VLOOKUP(D15,'Master sheet (Clientes)'!A$6:D$747,3,0)," ") -> Vivmark Residential | C15: =IFERROR(VLOOKUP(D15,'Master sheet (Clientes)'!A$6:D$747,4,0)," ") -> N-O | D15: Avalon at Edgewater II New Building (Russell). | E15: 155 | G15: Occupied | H15: Continue Left side bedroom bathroom tile floor to be demoed, sub floor fixed, install new tiles, and grout area is 9ft x 6ft. at 9am Bc to provide all materials and labor needed to complete the job. For access, please call Christian 201-705-0879 or Alex 201-713-8719 | I15: AJ Canas Solutions Carlos / Willian Alvarez | J15: Email | N15: Done
A16: =IFERROR(VLOOKUP(D16,'Master sheet (Clientes)'!A$6:D$747,2,0)," ") -> NJ | B16: =IFERROR(VLOOKUP(D16,'Master sheet (Clientes)'!A$6:D$747,3,0)," ") -> Vivmark Residential | C16: =IFERROR(VLOOKUP(D16,'Master sheet (Clientes)'!A$6:D$747,4,0)," ") -> N-O | D16: Avalon at Edgewater I Old Building (River Mews). | E16: 426 | G16: Occupied | H16: Continue Make opening in guest bedroom 3x3 to reinstall loose Hvac vent, close opening, spackle, sand and paint NOTE: Bc to provide carpet film, plastic drop, spackle, mesh tape, trash bags, sanding sponge, blue tape and all other materials and labor needed to complete the job. / For access, please call Christian 201-705-0879 or Alex 201-713-8719 update the scope of work. Two more openings of 2x4 were required to see where ducts weren't connected. After the ducts were taped with duct tape, there still wasn't air flow. The building asked to please just temporarily close openings so they can do their own investigation tomorrow to see where the problem is. Once they determine and fix it, they will let us know so we can close all openings properly. | I16: AJ Canas Solutions Javier | J16: Email | N16: Continue
A17: =IFERROR(VLOOKUP(D17,'Master sheet (Clientes)'!A$6:D$747,2,0)," ") -> NJ | B17: =IFERROR(VLOOKUP(D17,'Master sheet (Clientes)'!A$6:D$747,3,0)," ") -> Vivmark Residential | C17: =IFERROR(VLOOKUP(D17,'Master sheet (Clientes)'!A$6:D$747,4,0)," ") -> N-O | D17: Avalon at Edgewater II New Building (Russell). | E17: 151 | G17: Occupied | H17: Make opening in bedroom ceiling to try to determine where leak is coming from once repaired, close opening, plaster, sand and paint ceiling at 9am The building will provide the paint Bc to provide all other materials and labor needed to complete the job. For access, please call Christian 201-705-0879 or Alex 201-713-8719 | I17: AJ Canas Solutions Ricardo | J17: Email | N17: Continue
A18: =IFERROR(VLOOKUP(D18,'Master sheet (Clientes)'!A$6:D$747,2,0)," ") -> NJ | B18: =IFERROR(VLOOKUP(D18,'Master sheet (Clientes)'!A$6:D$747,3,0)," ") -> Vivmark Residential | C18: =IFERROR(VLOOKUP(D18,'Master sheet (Clientes)'!A$6:D$747,4,0)," ") -> N-O | D18: Avalon at Edgewater II New Building (Russell). | E18: 116 | G18: Vacant | H18: Purchase and Install 24-inch grab bar by toilet wall in master bathroom NOTE: Bc to provide 24-inch grab bar, plastic drop, rosin paper, blue tape, and trash bags. / For access, please call Christian 201-705-0879 or Alex 201-713-8719 | I18: AJ Canas Solutions Marlon | J18: Email | N18: Done
A19: =IFERROR(VLOOKUP(D19,'Master sheet (Clientes)'!A$6:D$747,2,0)," ") -> NJ | B19: =IFERROR(VLOOKUP(D19,'Master sheet (Clientes)'!A$6:D$747,3,0)," ") -> Vivmark Residential | C19: =IFERROR(VLOOKUP(D19,'Master sheet (Clientes)'!A$6:D$747,4,0)," ") -> N-O | D19: Avalon at Edgewater I Old Building (River Mews). | E19: 313 | F19: 2BDR | G19: Vacant | H19: Paint unit ( Paint kitchen and livinroom ceiling) at 8:00am | I19: AJ Canas Solutions William Diaz | J19: Email | N19: Done
A20: =IFERROR(VLOOKUP(D20,'Master sheet (Clientes)'!A$6:D$747,2,0)," ") -> NJ | B20: =IFERROR(VLOOKUP(D20,'Master sheet (Clientes)'!A$6:D$747,3,0)," ") -> Vivmark Residential | C20: =IFERROR(VLOOKUP(D20,'Master sheet (Clientes)'!A$6:D$747,4,0)," ") -> N-O | D20: Avalon Hoboken 800 Madison St, Hoboken, NJ 07030. | E20: 420 | G20: Occupied | H20: Sheetrock replacement / Last Minute request assigned by Roberto | I20: AJ Canas Solutions Vinicio | J20: Email | N20: Continue
A22: State | B22: MANAGEMENT | C22: BC CLERK | D22: BUILDING / ADDRESS | E22: UNIT / AREA | F22: SIZE | G22: WORKSITE STATUS | H22: JOB DESCRIPTION | I22: JOB AWARDED TO: / TECHS QUANTITY: | J22: REQUEST / P.O / WTN / W.O | K22: BC WORK ORDER / BC ESTIMATE | L22: EXTRAS | M22: SPECIAL NOTES / SEQUENCE | N22: VENDORS DAILY STATUS REPORT
A23: =IFERROR(VLOOKUP(D23,'Master sheet (Clientes)'!A$6:D$747,2,0)," ") -> NJ | B23: =IFERROR(VLOOKUP(D23,'Master sheet (Clientes)'!A$6:D$747,3,0)," ") -> Vivmark Residential | C23: =IFERROR(VLOOKUP(D23,'Master sheet (Clientes)'!A$6:D$747,4,0)," ") -> N-O | D23: Avalon Hoboken 800 Madison St, Hoboken, NJ 07030. | E23: 520 | G23: Occupied | H23: Provide a certified plumber to replace a supply valve They have the valve Wednesday 09/92 /2026 Requested by Ian / Last Minute request assigned by Roberto | I23: Hydro Jersey | J23: Email | M23: Job done 09/02 / This leak at unit 520 damaged the unit 420 drywall | N23: Done
A25: State | B25: MANAGEMENT | C25: BC CLERK | D25: BUILDING / ADDRESS | E25: UNIT / AREA | F25: SIZE | G25: WORKSITE STATUS | H25: JOB DESCRIPTION | I25: JOB AWARDED TO: / TECHS QUANTITY: | J25: REQUEST / P.O / WTN / W.O | K25: BC WORK ORDER / BC ESTIMATE | L25: EXTRAS | M25: SPECIAL NOTES / SEQUENCE | N25: VENDORS DAILY STATUS REPORT
A26: =IFERROR(VLOOKUP(D26,'Master sheet (Clientes)'!A$6:D$747,2,0)," ") -> NJ | B26: =IFERROR(VLOOKUP(D26,'Master sheet (Clientes)'!A$6:D$747,3,0)," ") -> Vivmark Residential | C26: =IFERROR(VLOOKUP(D26,'Master sheet (Clientes)'!A$6:D$747,4,0)," ") -> N-O | D26: Avalon North Bergen 5665 John F. Kennedy Blvd, North Bergen, NJ 07047. | E26: 505 | G26: Occupied | H26: Purchase and install fire dumper (requires scaffolding) Note: Send two (2) people to assemble the scaffolding and disassemble the bed; the bed must be reassembled after the work is finished at 9:00am | I26: Perfect Weather Solutions / Atlas 2 Laborers with tools: Carlos Marin / Oscar Salazar | J26: Email | N26: Done
A27: =IFERROR(VLOOKUP(D27,'Master sheet (Clientes)'!A$6:D$747,2,0)," ") -> NJ | B27: =IFERROR(VLOOKUP(D27,'Master sheet (Clientes)'!A$6:D$747,3,0)," ") -> Greystar | C27: =IFERROR(VLOOKUP(D27,'Master sheet (Clientes)'!A$6:D$747,4,0)," ") -> A-V | D27: The Grand 508 51st St, West New York, NJ 07093 | E27: 411 | F27: 2BDR | G27: Vacant | H27: Paint unit and cleaning at 8:00am Note: The property will provide the paint. | I27: Atlas Armando Gaona | J27: Email | N27: Paint done
A28: =IFERROR(VLOOKUP(D28,'Master sheet (Clientes)'!A$6:D$747,2,0)," ") -> NJ | B28: =IFERROR(VLOOKUP(D28,'Master sheet (Clientes)'!A$6:D$747,3,0)," ") -> Greystar | C28: =IFERROR(VLOOKUP(D28,'Master sheet (Clientes)'!A$6:D$747,4,0)," ") -> A-V | D28: Twenty50 2050 Central Rd, Fort Lee, NJ 07024 | E28: 520 | F28: 1BDR + Den | G28: Vacant | H28: Paint unit at 8:00 am NOTE: For access call Willie:+1 (386) 518-9413 | I28: Atlas Douglas Espinal | J28: Email | M28: Make ready 09/04 | N28: Paint done
A30: State | B30: MANAGEMENT | C30: BC CLERK | D30: BUILDING / ADDRESS | E30: UNIT / AREA | F30: SIZE | G30: WORKSITE STATUS | H30: JOB DESCRIPTION | I30: JOB AWARDED TO: / TECHS QUANTITY: | J30: REQUEST / P.O / WTN / W.O | K30: BC WORK ORDER / BC ESTIMATE | L30: EXTRAS | M30: SPECIAL NOTES / SEQUENCE | N30: VENDORS DAILY STATUS REPORT
A31: =IFERROR(VLOOKUP(D31,'Master sheet (Clientes)'!A$6:D$747,2,0)," ") -> NJ | B31: =IFERROR(VLOOKUP(D31,'Master sheet (Clientes)'!A$6:D$747,3,0)," ") -> Vivmark Residential | C31: =IFERROR(VLOOKUP(D31,'Master sheet (Clientes)'!A$6:D$747,4,0)," ") -> N-O | D31: Avalon at Edgewater I Old Building (River Mews). | E31: 432 | F31: 3BDR | G31: Vacant | H31: Paint unit at 8:00am | I31: DVM Ignacio Luc / Celestino Luc | J31: Email | N31: Done
A33: State | B33: MANAGEMENT | C33: BC CLERK | D33: BUILDING / ADDRESS | E33: UNIT / AREA | F33: SIZE | G33: WORKSITE STATUS | H33: JOB DESCRIPTION | I33: JOB AWARDED TO: / TECHS QUANTITY: | J33: REQUEST / P.O / WTN / W.O | K33: BC WORK ORDER / BC ESTIMATE | L33: EXTRAS | M33: SPECIAL NOTES / SEQUENCE | N33: VENDORS DAILY STATUS REPORT
A34: =IFERROR(VLOOKUP(D34,'Master sheet (Clientes)'!A$6:D$747,2,0)," ") -> NJ | B34: =IFERROR(VLOOKUP(D34,'Master sheet (Clientes)'!A$6:D$747,3,0)," ") -> Vivmark Residential | C34: =IFERROR(VLOOKUP(D34,'Master sheet (Clientes)'!A$6:D$747,4,0)," ") -> N-O | D34: Avalon Hoboken 800 Madison St, Hoboken, NJ 07030. | E34: 606 | H34: Balcony door threshold and kitchen transition strip repair replacement. 1 transition of 36" and 1 transition of 72". at 9:00 am For access call Felix:+1 (848) 242-6308 Note: Build care provides the new transitions. | I34: M&J Flooring | J34: Email | N34: Done
A35: =IFERROR(VLOOKUP(D35,'Master sheet (Clientes)'!A$6:D$747,2,0)," ") -> NJ | B35: =IFERROR(VLOOKUP(D35,'Master sheet (Clientes)'!A$6:D$747,3,0)," ") -> Vivmark Residential | C35: =IFERROR(VLOOKUP(D35,'Master sheet (Clientes)'!A$6:D$747,4,0)," ") -> N-O | D35: Avalon Hoboken 800 Madison St, Hoboken, NJ 07030. | E35: 537 | H35: Balcony door threshold at 9:00 am For access call Felix:+1 (848) 242-6308 Last minute request / assigned by Property | I35: M&J Flooring | J35: Email pending roberto | N35: Done
